Workbook

Sheet 대시보드
A1: INNO NanoLab — ICP 간섭 DB · 인터랙티브 뷰어 | O1: =MATCH($C$4,피크Top!$A:$A,0) -> 64
A2: 아래 노란 칸에서 분석선(원소·파장)을 고르면 → 그 피크의 주요 간섭선이 오른쪽 막대그래프로 갱신됩니다.
A4: 분석선 선택 ▶ | C4: Ho 345.314
A6: 기준강도 I(ref) | C6: =INDEX(피크Top!$AG:$AG,$O$1) -> 13088.5
A7: 최악 REE 간섭비 | C7: =INDEX(피크Top!$AH:$AH,$O$1) -> 0.2285747
A8: 판정 (REE 매트릭스) | C8: =INDEX(피크Top!$AI:$AI,$O$1) -> High risk
A9: 간섭선 수 (±~2nm) | C9: =INDEX(피크Top!$AK:$AK,$O$1) -> 39
A11: 주요 간섭선 (강도비 큰 순 · 상위 15)
A12: 간섭원소·파장 | B12: 강도비
A13: =INDEX(피크Top!$B:$P,$O$1,1) -> Co 345.351 | B13: =INDEX(피크Top!$Q:$AE,$O$1,1) -> 0.38938763
A14: =INDEX(피크Top!$B:$P,$O$1,2) -> Tb 345.406 | B14: =INDEX(피크Top!$Q:$AE,$O$1,2) -> 0.24820262
A15: =INDEX(피크Top!$B:$P,$O$1,3) -> Yb 345.407 | B15: =INDEX(피크Top!$Q:$AE,$O$1,3) -> 0.2285747
A16: =INDEX(피크Top!$B:$P,$O$1,4) -> Gd 345.415 | B16: =INDEX(피크Top!$Q:$AE,$O$1,4) -> 0.13663139
A17: =INDEX(피크Top!$B:$P,$O$1,5) -> La 345.316 | B17: =INDEX(피크Top!$Q:$AE,$O$1,5) -> 0.10859151
A18: =INDEX(피크Top!$B:$P,$O$1,6) -> La 345.218 | B18: =INDEX(피크Top!$Q:$AE,$O$1,6) -> 0.098269473
A19: =INDEX(피크Top!$B:$P,$O$1,7) -> Ni 345.288 | B19: =INDEX(피크Top!$Q:$AE,$O$1,7) -> 0.064835543
A20: =INDEX(피크Top!$B:$P,$O$1,8) -> Th 345.268 | B20: =INDEX(피크Top!$Q:$AE,$O$1,8) -> 0.051014249
A21: =INDEX(피크Top!$B:$P,$O$1,9) -> Ti 345.248 | B21: =INDEX(피크Top!$Q:$AE,$O$1,9) -> 0.050318982
A22: =INDEX(피크Top!$B:$P,$O$1,10) -> Re 345.187 | B22: =INDEX(피크Top!$Q:$AE,$O$1,10) -> 0.050219658
A23: =INDEX(피크Top!$B:$P,$O$1,11) -> Sm 345.356 | B23: =INDEX(피크Top!$Q:$AE,$O$1,11) -> 0.046949612
A24: =INDEX(피크Top!$B:$P,$O$1,12) -> Cr 345.332 | B24: =INDEX(피크Top!$Q:$AE,$O$1,12) -> 0.036444207
A25: =INDEX(피크Top!$B:$P,$O$1,13) -> Sm 345.277 | B25: =INDEX(피크Top!$Q:$AE,$O$1,13) -> 0.034259082
A26: =INDEX(피크Top!$B:$P,$O$1,14) -> Nb 345.234 | B26: =INDEX(피크Top!$Q:$AE,$O$1,14) -> 0.025319937
A27: =INDEX(피크Top!$B:$P,$O$1,15) -> U 345.357 | B27: =INDEX(피크Top!$Q:$AE,$O$1,15) -> 0.023203576

Sheet 피크 요약
A1: ICP 간섭 DB — 전체 피크 요약 (166개, 기준원소 18종)
A2: 판정 기준 매트릭스 = Y·Lu·Tm·Ho·Yb·Nd·Er·Gd·Dy·Ce · 강도비 = 간섭강도/기준강도
A4: 분석원소 | B4: 파장 (nm) | C4: 이온 | D4: 기준강도 I(ref) | E4: 간섭선 수 | F4: 최악 REE 간섭 | G4: REE 파장(nm) | H4: REE 간섭비 | I4: 판정(REE) | J4: 최악 전체 간섭 | L4: 원소 | M4: 최소 달성 REE간섭비
A5: Ce | B5: 380.153 | C5: II | D5: 10044 | E5: 37 | F5: Nd | G5: 380.347 | H5: 0.31532258 | I5: High risk | J5: Pr @380.030 (45.8%) | L5: Co 231.16 | M5: 0
A6: Ce | B6: 394.274 | C6: II | D6: 6991.4 | E6: 39 | F6: Nd | G6: 394.151 | H6: 0.89156678 | I6: High risk | J6: Al @394.401 (108.4%) | L6: Fe 239.56 | M6: 0
A7: Ce | B7: 399.924 | C7: II | D7: 7989 | E7: 39 | F7: Dy | G7: 400.045 | H7: 3.0971961 | I7: High risk | J7: Dy @400.045 (309.7%) | L7: Lu 219.56 | M7: 0
A8: Ce | B8: 407.347 | C8: II | D8: 10588 | E8: 40 | F8: Gd | G8: 407.375 | H8: 0.79378542 | I8: High risk | J8: Gd @407.375 (79.4%) | L8: Ni 216.56 | M8: 0
A9: Ce | B9: 407.57 | C9: II | D9: 11561.2 | E9: 41 | F9: Gd | G9: 407.375 | H9: 0.72696606 | I9: High risk | J9: La @407.734 (564.9%) | L9: Ta 226.14 | M9: 0
A10: Ce | B10: 408.322 | C10: II | D10: 9540.5 | E10: 40 | F10: Nd | G10: 408.252 | H10: 0.093464703 | I10: Caution | J10: Pr @408.185 (63.0%) | L10: Yb 211.67 | M10: 0
A11: Ce | B11: 413.38 | C11: II | D11: 9654 | E11: 39 | F11: Gd | G11: 413.226 | H11: 0.49224156 | I11: High risk | J11: Gd @413.226 (49.2%) | L11: Dy 353.17 | M11: 0.0038024894
A12: Ce | B12: 413.765 | C12: II | D12: 6591.2 | E12: 38 | F12: Gd | G12: 413.71 | H12: 0.20481855 | I12: High risk | J12: Gd @413.710 (20.5%) | L12: Sc 361.38 | M12: 0.004767063
A13: Ce | B13: 418.659 | C13: II | D13: 14417.5 | E13: 37 | F13: Gd | G13: 418.426 | H13: 7.4613491 | I13: High risk | J13: Gd @418.426 (746.1%) | L13: Y 371.03 | M13: 0.0099073016
A14: Ce | B14: 422.26 | C14: II | D14: 11589 | E14: 37 | F14: Nd | G14: 422.113 | H14: 0.085883165 | I14: Caution | J14: Pr @422.293 (203.7%) | L14: La 379.48 | M14: 0.017639397
A15: Ce | B15: 446.021 | C15: II | D15: 25595.5 | E15: 40 | F15: Nd | G15: 446.298 | H15: 0.50880819 | I15: High risk | J15: Sm @445.851 (58.6%) | L15: Er 369.26 | M15: 0.019557747
A16: Co | B16: 228.615 | C16: II | D16: 6936.5 | E16: 38 | F16: Ce | G16: 228.464 | H16: 0.0023643048 | I16: Excellent | J16: Ni @228.708 (9.0%) | L16: Tm 313.12 | M16: 0.023554513
A17: Co | B17: 230.786 | C17: II | D17: 21829 | E17: 40 | F17: Ce | G17: 230.854 | H17: 0.00077419946 | I17: Excellent | J17: Mo @230.699 (3.9%) | L17: Tb 350.91 | M17: 0.027587655
A18: Co | B18: 231.16 | C18: II | D18: 13310.5 | E18: 39 | F18: - | H18: 0 | I18: Excellent | J18: Ni @231.096 (36.8%) | L18: Ho 341.64 | M18: 0.038840486
A19: Co | B19: 236.379 | C19: II | D19: 9708.5 | E19: 40 | F19: Yb | G19: 236.209 | H19: 0.032559098 | I19: Good | J19: Fe @236.483 (38.8%) | L19: Pr 422.53 | M19: 0.054284004
A20: Co | B20: 237.863 | C20: II | D20: 15306 | E20: 38 | F20: - | H20: 0 | I20: Excellent | J20: Fe @237.928 (9.7%) | L20: Gd 376.84 | M20: 0.055969754
A21: Co | B21: 238.345 | C21: II | D21: 10677 | E21: 39 | F21: - | H21: 0 | I21: Excellent | J21: Fe @238.325 (12.6%) | L21: Ce 422.26 | M21: 0.085883165
A22: Co | B22: 238.892 | C22: II | D22: 273225 | E22: 38 | F22: - | H22: 0 | I22: Excellent | J22: Fe @238.863 (3.1%) | L22: Nd 430.36 | M22: 0.11600319
A23: Dy | B23: 340.78 | C23: II | D23: 27582.9 | E23: 40 | F23: Gd | G23: 340.756 | H23: 0.18242824 | I23: Caution | J23: Gd @340.756 (18.2%)
A24: Dy | B24: 352.398 | C24: II | D24: 24487 | E24: 37 | F24: Gd | G24: 352.419 | H24: 0.2123004 | I24: High risk | J24: Ni @352.453 (52.8%)
A25: Dy | B25: 353.171 | C25: II | D25: 87732 | E25: 40 | F25: Nd | G25: 353.359 | H25: 0.0038024894 | I25: Excellent | J25: V @353.076 (4.3%)
A26: Dy | B26: 353.602 | C26: II | D26: 15894.4 | E26: 36 | F26: Ce | G26: 353.67 | H26: 0.013017163 | I26: Good | J26: Sc @353.571 (194.3%)
A27: Dy | B27: 357.625 | C27: II | D27: 12386.1 | E27: 39 | F27: Ce | G27: 357.746 | H27: 0.42624393 | I27: High risk | J27: Sc @357.634 (1618.3%)
A28: Dy | B28: 364.54 | C28: II | D28: 16509.7 | E28: 39 | F28: Gd | G28: 364.62 | H28: 0.80971187 | I28: High risk | J28: Sc @364.531 (217.0%)
A29: Dy | B29: 387.211 | C29: II | D29: 35902.3 | E29: 36 | F29: Ce | G29: 387.087 | H29: 0.020110132 | I29: Good | J29: La @387.164 (213.8%)
A30: Dy | B30: 389.853 | C30: II | D30: 17081.9 | E30: 40 | F30: Ce | G30: 389.826 | H30: 0.12229319 | I30: Caution | J30: Tb @389.919 (60.3%)
A31: Dy | B31: 394.468 | C31: II | D31: 20625.2 | E31: 40 | F31: Ce | G31: 394.388 | H31: 0.1306751 | I31: Caution | J31: Al @394.401 (36.8%)
A32: Dy | B32: 400.045 | C32: II | D32: 24743.5 | E32: 39 | F32: Ce | G32: 399.924 | H32: 0.32263019 | I32: High risk | J32: Zr @399.895 (39.4%)
A33: Dy | B33: 407.797 | C33: II | D33: 28806.5 | E33: 28 | F33: Gd | G33: 407 | H33: 0.22962873 | I33: High risk | J33: Sr @407.771 (13431.9%)
A34: Er | B34: 291.036 | C34: II | D34: 5866.7 | E34: 39 | F34: Lu | G34: 291.139 | H34: 4.3991 | I34: High risk | J34: Lu @291.139 (439.9%)
... A45: Fe | B45: 238.204 | C45: II | D45: 41015 | E45: 40 | F45: Dy | G45: 238.198 | H45: 0.0069681824 | I45: Excellent | J45: Ta @238.115 (3.4%)
A46: Fe | B46: 239.563 | C46: II | D46: 10719.4 | E46: 39 | F46: - | H46: 0 | I46: Excellent | J46: Hf @239.384 (40.4%)
A47: Fe | B47: 240.489 | C47: II | D47: 10535 | E47: 40 | F47: Ce | G47: 240.52 | H47: 0.00049359279 | I47: Excellent | J47: Hf @240.543 (34.8%)
A48: Fe | B48: 258.588 | C48: II | D48: 20375 | E48: 36 | F48: - | H48: 0 | I48: Excellent | J48: Co @258.722 (22.0%)
A49: Fe | B49: 259.94 | C49: II | D49: 27160 | E49: 40 | F49: Dy | G49: 260.016 | H49: 0.0052835052 | I49: Excellent | J49: Mn @259.889 (8.8%)
A50: Fe | B50: 260.709 | C50: II | D50: 6040 | E50: 37 | F50: - | H50: 0 | I50: Excellent | J50: Hf @260.703 (60.1%)
A51: Fe | B51: 261.187 | C51: II | D51: 8669.2 | E51: 39 | F51: Lu | G51: 261.34 | H51: 0.62882388 | I51: High risk | J51: Lu @261.340 (62.9%)
...

Sheet 원소 간섭 히트맵
A1: 원소 간섭 히트맵 — 각 분석원소의 '가장 깨끗한 선'에서 간섭원소별 강도비(%)
A2: 행=분석원소(권장선). 열=간섭원소. 색 진할수록 간섭 큼. 0=흰색·5%=주황·≥20%=빨강.
A4: 분석원소 (권장선 nm) | B4: Y | C4: Lu | D4: Tm | E4: Ho | F4: Yb | G4: Nd | H4: Er | I4: Gd | J4: Dy | K4: Ce | L4: Zr | M4: Ti | N4: Fe | O4: Ni | P4: Ca | Q4: Cr | R4: Co | S4: Mn
A5: Ce 413.765 | B5: 0 | C5: 0 | D5: 0 | E5: 0.017978517 | F5: 0 | G5: 0.059276004 | H5: 0 | I5: 0.20481855 | J5: 0 | K5: — | L5: 0 | M5: 0 | N5: 0.0066755674 | O5: 0 | P5: 0.090757373 | Q5: 0.0089968443 | R5: 0 | S5: 0.00028826314
A6: Co 238.892 | B6: 0 | C6: 0 | D6: 0 | E6: 0 | F6: 0 | G6: 0 | H6: 0 | I6: 0 | J6: 0 | K6: 0 | L6: 0.00034074481 | M6: 0 | N6: 0.030597493 | O6: 0.0011682679 | P6: 0 | Q6: 0.00018116937 | R6: — | S6: 0.00017567939
A7: Dy 353.171 | B7: 0 | C7: 0 | D7: 0 | E7: 0 | F7: 0 | G7: 0.0038024894 | H7: 0 | I7: 0 | J7: — | K7: 0.0032622076 | L7: 0.0087128984 | M7: 0 | N7: 0.00038868372 | O7: 0.00023366617 | P7: 0 | Q7: 0.00019377194 | R7: 0.0037318196 | S7: 0.0079913828
A8: Er 349.910 | B8: 0 | C8: 0 | D8: 0 | E8: 0.0094580343 | F8: 0 | G8: 0 | H8: — | I8: 0.00048038681 | J8: 0.06545773 | K8: 0.0080034677 | L8: 0.051640465 | M8: 0.011953811 | N8: 0.0033694108 | O8: 0.0096479547 | P8: 0 | Q8: 0 | R8: 1.1171786e-05 | S8: 0
A9: Fe 238.204 | B9: 0 | C9: 0 | D9: 0 | E9: 0 | F9: 0 | G9: 0 | H9: 0 | I9: 0 | J9: 0.0069681824 | K9: 0 | L9: 0 | M9: 0 | N9: — | O9: 2.4381324e-06 | P9: 0 | Q9: 0.0029330733 | R9: 0.028257954 | S9: 1.7066927e-05
A10: Gd 301.013 | B10: 0 | C10: 0 | D10: 0.048041242 | E10: 0 | F10: 0.068239895 | G10: 0 | H10: 0.053663089 | I10: — | J10: 0.012643602 | K10: 0.0038441882 | L10: 0.0059403447 | M10: 0 | N10: 0.0084512884 | O10: 2.9627654e-05 | P10: 0.0031923798 | Q10: 0.00064440148 | R10: 0 | S10: 0.0015850795
A11: Ho 381.074 | B11: 0 | C11: 0 | D11: 0 | E11: — | F11: 0 | G11: 0.067454597 | H11: 0.0061014397 | I11: 0.0041403971 | J11: 0.010742448 | K11: 0.021676861 | L11: 0 | M11: 0 | N11: 0.0010162793 | O11: 0 | P11: 0 | Q11: 0.0010915592 | R11: 0.0010539193 | S11: 0.0053072363
A12: La 333.749 | B12: 0.0021072451 | C12: 0 | D12: 0 | E12: 0.04600032 | F12: 0 | G12: 0 | H12: 0.040805288 | I12: 0 | J12: 0 | K12: 0.0022591601 | L12: 0.036247838 | M12: 0.007413912 | N12: 0.00052940073 | O12: 0.00054090944 | P12: 0 | Q12: 0.010353237 | R12: 0.00033375263 | S12: 0.00043618017
A13: Lu 261.541 | B13: 0 | C13: — | D13: 0.00032961121 | E13: 0 | F13: 0.00044297835 | G13: 0 | H13: 0.00083921807 | I13: 0 | J13: 0 | K13: 0 | L13: 0 | M13: 0 | N13: 0 | O13: 0 | P13: 0 | Q13: 0.00014021589 | R13: 0.0019375759 | S13: 0.00011373067
A14: Nd 410.945 | B14: 0.0011369865 | C14: 0 | D14: 0 | E14: 0.028134753 | F14: 0 | G14: — | H14: 0 | I14: 0.21593684 | J14: 0 | K14: 0.095330202 | L14: 0.019432956 | M14: 0 | N14: 0.00057528798 | O14: 0 | P14: 0.0072205437 | Q14: 0.0017439833 | R14: 0.0054403218 | S14: 0.0018436394
A15: Ni 221.648 | B15: 0 | C15: 0 | D15: 0 | E15: 0 | F15: 0 | G15: 0 | H15: 0 | I15: 0 | J15: 0 | K15: 0.0010146747 | L15: 0 | M15: 0 | N15: 0.0014674733 | O15: — | P15: 0 | Q15: 0.0031708585 | R15: 0.019519805 | S15: 0
A16: Pr 400.869 | B16: 0 | C16: 0 | D16: 0 | E16: 0 | F16: 0.0078854631 | G16: 0.22157221 | H16: 0.23452856 | I16: 0.1408567 | J16: 0.035345018 | K16: 0.11025692 | L16: 0.0062804573 | M16: 0.031402287 | N16: 0.0011863086 | O16: 0 | P16: 0 | Q16: 0 | R16: 0.00030239239 | S16: 0.0031402287
A17: Sc 335.372 | B17: 0 | C17: 0 | D17: 0.005594014 | E17: 0.0076755149 | F17: 0.00012623786 | G17: 0.0034963774 | H17: 0 | I17: 0 | J17: 0.0059350777 | K17: 0.0021311735 | L17: 0.007048755 | M17: 0.0081573702 | N17: 7.5932547e-06 | O17: 0 | P17: 0 | Q17: 0.00094187996 | R17: 0.00078526909 | S17: 0
A18: Ta 263.558 | B18: 0 | C18: 0 | D18: 0 | E18: 0 | F18: 0.027477745 | G18: 0 | H18: 0 | I18: 0 | J18: 0.12137982 | K18: 0.031305638 | L18: 0.0017655786 | M18: 0.007462908 | N18: 0.0068545994 | O18: 0 | P18: 0 | Q18: 0.0037091988 | R18: 0.0047032641 | S18: 0.0038575668
A19: Tb 350.914 | B19: 0.004498043 | C19: 0 | D19: 0 | E19: 0.027587655 | F19: 0.012743601 | G19: 0 | H19: 0 | I19: 0 | J19: 0 | K19: 0.022477407 | L19: 0.049980532 | M19: 0.0079125597 | N19: 0.00069161253 | O19: 0.046676161 | P19: 0 | Q19: 0.00051230558 | R19: 0.10827578 | S19: 8.4530421e-05
A20: Tm 329.100 | B20: 0 | C20: 0 | D20: — | E20: 0.04620004 | F20: 0 | G20: 0.010590368 | H20: 0.025481975 | I20: 0.068736878 | J20: 0 | K20: 0.0091895928 | L20: 0 | M20: 0.0054339849 | N20: 0.00065731115 | O20: 8.9343263e-05 | P20: 0 | Q20: 0.0047607196 | R20: 0.00013401489 | S20: 4.4671632e-05
A21: Y 377.433 | B21: — | C21: 0 | D21: 0 | E21: 0 | F21: 5.7329529e-05 | G21: 0.018045572 | H21: 0.0077913884 | I21: 0.0035242395 | J21: 0.0028183061 | K21: 0.00096578207 | L21: 0 | M21: 0.0002788454 | N21: 1.4247575e-05 | O21: 0.00092914545 | P21: 0 | Q21: 0 | R21: 3.4940482e-05 | S21: 1.1194524e-05
A22: Yb 328.937 | B22: 9.3753521e-05 | C22: 0 | D22: 4.1261996e-05 | E22: 0.0030130397 | F22: — | G22: 0.00043338153 | H22: 0 | I22: 0 | J22: 0.00050493714 | K22: 0.00037605869 | L22: 0.0030665758 | M22: 0.0014008186 | N22: 5.4841893e-06 | O22: 3.6561262e-06 | P22: 0 | Q22: 2.4025972e-05 | R22: 0 | S22: 1.8280631e-06

Sheet 전체 데이터
A1: 분석원소 | B1: 분석파장(nm) | C1: 기준강도 I(ref) | D1: 간섭원소 | E1: 간섭파장(nm) | F1: Δλ(nm) | G1: |Δλ|(nm) | H1: 간섭강도 I | I1: 강도비(=간섭/기준) | J1: REE여부
A2: Ce | B2: 380.153 | C2: 10044 | D2: Ru | E2: 380.026 | F2: 0.127 | G2: 0.127 | H2: 58.2 | I2: =H2/C2 -> 0.0057945042
A3: Ce | B3: 380.153 | C3: 10044 | D3: Pr | E3: 380.03 | F3: 0.123 | G3: 0.123 | H3: 4600.6 | I3: =H3/C3 -> 0.4580446
A4: Ce | B4: 380.153 | C4: 10044 | D4: Ce | E4: 380.032 | F4: 0.121 | G4: 0.121 | H4: 885.5 | I4: =H4/C4 -> 0.088162087 | J4: Y
A5: Ce | B5: 380.153 | C5: 10044 | D5: Hf | E5: 380.037 | F5: 0.116 | G5: 0.116 | H5: 447 | I5: =H5/C5 -> 0.044504182
A6: Ce | B6: 380.153 | C6: 10044 | D6: Sm | E6: 380.037 | F6: 0.116 | G6: 0.116 | H6: 830.5 | I6: =H6/C6 -> 0.082686181
A7: Ce | B7: 380.153 | C7: 10044 | D7: Th | E7: 380.037 | F7: 0.116 | G7: 0.116 | H7: 383 | I7: =H7/C7 -> 0.038132218
A8: Ce | B8: 380.153 | C8: 10044 | D8: Mn | E8: 380.056 | F8: 0.097 | G8: 0.097 | H8: 33.4 | I8: =H8/C8 -> 0.0033253684
A9: Ce | B9: 380.153 | C9: 10044 | D9: Fe | E9: 380.069 | F9: 0.084 | G9: 0.084 | H9: 0.5 | I9: =H9/C9 -> 4.9780964e-05
A10: Ce | B10: 380.153 | C10: 10044 | D10: Zr | E10: 380.074 | F10: 0.079 | G10: 0.079 | H10: 363 | I10: =H10/C10 -> 0.03614098
A11: Ce | B11: 380.153 | C11: 10044 | D11: Y | E11: 380.087 | F11: 0.066 | G11: 0.066 | H11: 434.4 | I11: =H11/C11 -> 0.043249701 | J11: Y
A12: Ce | B12: 380.153 | C12: 10044 | D12: Sm | E12: 380.089 | F12: 0.064 | G12: 0.064 | H12: 4334.7 | I12: =H12/C12 -> 0.43157109
A13: Ce | B13: 380.153 | C13: 10044 | D13: Sn | E13: 380.101 | F13: 0.052 | G13: 0.052 | H13: 176.5 | I13: =H13/C13 -> 0.01757268
A14: Ce | B14: 380.153 | C14: 10044 | D14: Nd | E14: 380.111 | F14: 0.042 | G14: 0.042 | H14: 1744.4 | I14: =H14/C14 -> 0.17367583 | J14: Y
A15: Ce | B15: 380.153 | C15: 10044 | D15: Cr | E15: 380.119 | F15: 0.034 | G15: 0.034 | H15: 10.1 | I15: =H15/C15 -> 0.0010055755
A16: Ce | B16: 380.153 | C16: 10044 | D16: Co | E16: 380.123 | F16: 0.03 | G16: 0.03 | H16: 3 | I16: =H16/C16 -> 0.00029868578
A17: Ce | B17: 380.153 | C17: 10044 | D17: Nb | E17: 380.129 | F17: 0.024 | G17: 0.024 | H17: 922.8 | I17: =H17/C17 -> 0.091875747
A18: Ce | B18: 380.153 | C18: 10044 | D18: Th | E18: 380.144 | F18: 0.009 | G18: 0.009 | H18: 90.5 | I18: =H18/C18 -> 0.0090103544
A19: Ce | B19: 380.153 | C19: 10044 | D19: W | E19: 380.151 | F19: 0.002 | G19: 0.002 | H19: 8.6 | I19: =H19/C19 -> 0.00085623258
A20: Ce | B20: 380.153 | C20: 10044 | D20: Tb | E20: 380.18 | F20: 0.027 | G20: 0.027 | H20: 1462.6 | I20: =H20/C20 -> 0.14561928
A21: Ce | B21: 380.153 | C21: 10044 | D21: Mo | E21: 380.184 | F21: 0.031 | G21: 0.031 | H21: 54.4 | I21: =H21/C21 -> 0.0054161689
A22: Ce | B22: 380.153 | C22: 10044 | D22: Mn | E22: 380.19 | F22: 0.037 | G22: 0.037 | H22: 26.5 | I22: =H22/C22 -> 0.0026383911
A23: Ce | B23: 380.153 | C23: 10044 | D23: W | E23: 380.191 | F23: 0.038 | G23: 0.038 | H23: 8.6 | I23: =H23/C23 -> 0.00085623258
A24: Ce | B24: 380.153 | C24: 10044 | D24: Au | E24: 380.192 | F24: 0.039 | G24: 0.039 | H24: 17 | I24: =H24/C24 -> 0.0016925528
A25: Ce | B25: 380.153 | C25: 10044 | D25: Dy | E25: 380.193 | F25: 0.04 | G25: 0.04 | H25: 584 | I25: =H25/C25 -> 0.058144166 | J25: Y
A26: Ce | B26: 380.153 | C26: 10044 | D26: Th | E26: 380.215 | F26: 0.062 | G26: 0.062 | H26: 181.8 | I26: =H26/C26 -> 0.018100358
A27: Ce | B27: 380.153 | C27: 10044 | D27: U | E27: 380.228 | F27: 0.075 | G27: 0.075 | H27: 235 | I27: =H27/C27 -> 0.023397053
A28: Ce | B28: 380.153 | C28: 10044 | D28: Nd | E28: 380.229 | F28: 0.076 | G28: 0.076 | H28: 1176.4 | I28: =H28/C28 -> 0.11712465 | J28: Y
A29: Ce | B29: 380.153 | C29: 10044 | D29: Nb | E29: 380.292 | F29: 0.139 | G29: 0.139 | H29: 654.4 | I29: =H29/C29 -> 0.065153325
A30: Ce | B30: 380.153 | C30: 10044 | D30: Mo | E30: 380.306 | F30: 0.153 | G30: 0.153 | H30: 5.8 | I30: =H30/C30 -> 0.00057745918
A31: Ce | B31: 380.153 | C31: 10044 | D31: Th | E31: 380.308 | F31: 0.155 | G31: 0.155 | H31: 86 | I31: =H31/C31 -> 0.0085623258
A32: Ce | B32: 380.153 | C32: 10044 | D32: Ce | E32: 380.31 | F32: 0.157 | G32: 0.157 | H32: 3015.5 | I32: =H32/C32 -> 0.30022899 | J32: Y
A33: Ce | B33: 380.153 | C33: 10044 | D33: Ru | E33: 380.319 | F33: 0.166 | G33: 0.166 | H33: 17.6 | I33: =H33/C33 -> 0.0017522899
A34: Ce | B34: 380.153 | C34: 10044 | D34: U | E34: 380.335 | F34: 0.182 | G34: 0.182 | H34: 79.7 | I34: =H34/C34 -> 0.0079350856
A35: Ce | B35: 380.153 | C35: 10044 | D35: Nd | E35: 380.347 | F35: 0.194 | G35: 0.194 | H35: 3167.1 | I35: =H35/C35 -> 0.31532258 | J35: Y
A36: Ce | B36: 380.153 | C36: 10044 | D36: V | E36: 380.348 | F36: 0.195 | G36: 0.195 | H36: 272.2 | I36: =H36/C36 -> 0.027100757
A37: Ce | B37: 380.153 | C37: 10044 | D37: Ce | E37: 380.384 | F37: 0.231 | G37: 0.231 | H37: 163 | I37: =H37/C37 -> 0.016228594 | J37: Y
A38: Ce | B38: 380.153 | C38: 10044 | D38: Nb | E38: 380.387 | F38: 0.234 | G38: 0.234 | H38: 502.5 | I38: =H38/C38 -> 0.050029869
A39: Ce | B39: 394.274 | C39: 6991.4 | D39: Mo | E39: 394.149 | F39: 0.125 | G39: 0.125 | H39: 181.4 | I39: =H39/C39 -> 0.025946162
A40: Ce | B40: 394.274 | C40: 6991.4 | D40: Re | E40: 394.15 | F40: 0.124 | G40: 0.124 | H40: 1.2 | I40: =H40/C40 -> 0.00017163944
...

Sheet 피크Top
A1: key
A2: Ce 380.153 | B2: Pr 380.030 | C2: Sm 380.089 | D2: Nd 380.347 | E2: Nd 380.111 | F2: Tb 380.180 | G2: Nd 380.229 | H2: Nb 380.129 | I2: Sm 380.037 | J2: Nb 380.292 | K2: Dy 380.193 | L2: Nb 380.387 | M2: Hf 380.037 | N2: Y 380.087 | O2: Th 380.037 | P2: Zr 380.074 | Q2: 0.4580446 | R2: 0.43157109 | S2: 0.31532258 | T2: 0.17367583 | U2: 0.14561928 | V2: 0.11712465 | W2: 0.091875747 | X2: 0.082686181 | Y2: 0.065153325 | Z2: 0.058144166 | AA2: 0.050029869 | AB2: 0.044504182 | AC2: 0.043249701 | AD2: 0.038132218 | AE2: 0.03614098 | AF2: 380.153 | AG2: 10044 | AH2: 0.31532258 | AI2: High risk | AJ2: Ce | AK2: 37
A3: Ce 394.274 | B3: Al 394.401 | C3: Nd 394.151 | D3: Sm 394.188 | E3: Sm 394.324 | F3: Eu 394.307 | G3: Dy 394.253 | H3: Nd 394.262 | I3: Th 394.339 | J3: Er 394.318 | K3: Th 394.369 | L3: Eu 394.156 | M3: Er 394.442 | N3: U 394.413 | O3: Mo 394.149 | P3: Gd 394.264 | Q3: 1.084418 | R3: 0.89156678 | S3: 0.31294161 | T3: 0.2006179 | U3: 0.13612438 | V3: 0.09638985 | W3: 0.093443373 | X3: 0.084089024 | Y3: 0.058428927 | Z3: 0.046070887 | AA3: 0.035128873 | AB3: 0.03477129 | AC3: 0.033312355 | AD3: 0.025946162 | AE3: 0.023686243 | AF3: 394.274 | AG3: 6991.4 | AH3: 0.89156678 | AI3: High risk | AJ3: Ce | AK3: 39
A4: Ce 399.924 | B4: Dy 400.045 | C4: Zr 399.895 | D4: Ti 399.864 | E4: Pr 400.017 | F4: Nd 399.792 | G4: Nd 400.049 | H4: Gd 400.125 | I4: Pr 399.912 | J4: Tb 399.940 | K4: Gd 399.777 | L4: Pr 399.796 | M4: Th 399.787 | N4: Tb 400.000 | O4: V 399.920 | P4: Er 399.907 | Q4: 3.0971961 | R4: 1.2210039 | S4: 0.46059582 | T4: 0.29056202 | U4: 0.26461384 | V4: 0.25229691 | W4: 0.21241707 | X4: 0.21095256 | Y4: 0.16446364 | Z4: 0.14782826 | AA4: 0.11507072 | AB4: 0.11453248 | AC4: 0.065640255 | AD4: 0.056202278 | AE4: 0.049205157 | AF4: 399.924 | AG4: 7989 | AH4: 3.0971961 | AI4: High risk | AJ4: Ce | AK4: 39
A5: Ce 407.347 | B5: Gd 407.375 | C5: Dy 407.312 | D5: Sm 407.583 | E5: Nd 407.511 | F5: Er 407.400 | G5: Gd 407.319 | H5: W 407.436 | I5: Pr 407.251 | J5: Fe 407.174 | K5: Zr 407.270 | L5: Nd 407.148 | M5: Nd 407.441 | N5: Tb 407.522 | O5: Dy 407.261 | P5: Dy 407.399 | Q5: 0.79378542 | R5: 0.68124292 | S5: 0.54823385 | T5: 0.4644881 | U5: 0.45060446 | V5: 0.1954099 | W5: 0.082376275 | X5: 0.074442765 | Y5: 0.073772195 | Z5: 0.072062713 | AA5: 0.070183226 | AB5: 0.059775217 | AC5: 0.044569324 | AD5: 0.031526256 | AE5: 0.030638459 | AF5: 407.347 | AG5: 10588 | AH5: 0.79378542 | AI5: High risk | AJ5: Ce | AK5: 40
A6: Ce 407.570 | B6: La 407.734 | C6: Gd 407.375 | D6: Sm 407.583 | E6: Y 407.736 | F6: Nd 407.511 | G6: Er 407.400 | H6: Zr 407.704 | I6: Gd 407.319 | J6: La 407.670 | K6: Sm 407.662 | L6: W 407.436 | M6: Nd 407.441 | N6: Tb 407.522 | O6: Dy 407.399 | P6: U 407.668 | Q6: 5.6487648 | R6: 0.72696606 | S6: 0.50208456 | T6: 0.43814656 | U6: 0.42538837 | V6: 0.41267342 | W6: 0.40886759 | X6: 0.17896066 | Y6: 0.16643601 | Z6: 0.14777878 | AA6: 0.075441996 | AB6: 0.054743452 | AC6: 0.040817562 | AD6: 0.028059371 | AE6: 0.025092551 | AF6: 407.57 | AG6: 11561.2 | AH6: 0.72696606 | AI6: High risk | AJ6: Ce | AK6: 41
A7: Ce 408.322 | B7: Pr 408.185 | C7: Pr 408.334 | D7: Sm 408.259 | E7: Sc 408.239 | F7: Sm 408.358 | G7: Sm 408.437 | H7: Nd 408.252 | I7: Ar 408.405 | J7: Sm 408.195 | K7: Mn 408.363 | L7: Th 408.226 | M7: Gd 408.466 | N7: Mn 408.294 | O7: Eu 408.226 | P7: U 408.493 | Q7: 0.62970494 | R7: 0.35661653 | S7: 0.26680992 | T7: 0.22885593 | U7: 0.15871286 | V7: 0.12533934 | W7: 0.093464703 | X7: 0.059116399 | Y7: 0.052691159 | Z7: 0.051370473 | AA7: 0.0478172 | AB7: 0.04749227 | AC7: 0.046622294 | AD7: 0.03965201 | AE7: 0.027912583 | AF7: 408.322 | AG7: 9540.5 | AH7: 0.093464703 | AI7: Caution | AJ7: Ce | AK7: 40
A8: Ce 413.380 | B8: Gd 413.226 | C8: Nd 413.532 | D8: Nd 413.335 | E8: Th 413.275 | F8: Pr 413.361 | G8: Sm 413.514 | H8: V 413.448 | I8: Th 413.411 | J8: Nd 413.255 | K8: Dy 413.335 | L8: Sm 413.317 | M8: Yb 413.509 | N8: Nd 413.471 | O8: Rh 413.527 | P8: Sc 413.298 | Q8: 0.49224156 | R8: 0.29039776 | S8: 0.19196188 | T8: 0.14165113 | U8: 0.11753677 | V8: 0.090066294 | W8: 0.060389476 | X8: 0.052900352 | Y8: 0.051636627 | Z8: 0.048135488 | AA8: 0.035477522 | AB8: 0.033561218 | AC8: 0.030432981 | AD8: 0.02979076 | AE8: 0.01761964 | AF8: 413.38 | AG8: 9654 | AH8: 0.49224156 | AI8: High risk | AJ8: Ce | AK8: 39
A9: Ce 413.765 | B9: Gd 413.710 | C9: Ca 415.822 | D9: Th 414.023 | E9: Nd 413.675 | F9: Nb 413.709 | G9: Nb 413.970 | H9: Th 413.629 | I9: Sm 413.892 | J9: Eu 413.659 | K9: Sc 414.027 | L9: Ho 413.622 | M9: U 413.914 | N9: U 413.576 | O9: U 413.681 | P9: La 415.820 | Q9: 0.20481855 | R9: 0.090757373 | S9: 0.088997451 | T9: 0.059276004 | U9: 0.046744144 | V9: 0.038596917 | W9: 0.027946353 | X9: 0.023637577 | Y9: 0.021741109 | Z9: 0.019859813 | AA9: 0.017978517 | AB9: 0.015535866 | AC9: 0.012395315 | AD9: 0.012122224 | AE9: 0.0098312902 | AF9: 413.765 | AG9: 6591.2 | AH9: 0.20481855 | AI9: High risk | AJ9: Ce | AK9: 38
A10: Ce 418.659 | B10: Gd 418.426 | C10: Sm 418.813 | D10: Dy 418.682 | E10: Nd 418.497 | F10: Zr 418.667 | G10: Nd 418.603 | H10: Pr 418.512 | I10: Nd 418.823 | J10: Mo 418.832 | K10: U 418.806 | L10: Tb 418.621 | M10: Zr 418.751 | N10: La 418.730 | O10: Th 418.471 | P10: Hf 418.767 | Q10: 7.4613491 | R10: 0.33734697 | S10: 0.097333102 | T10: 0.088399514 | U10: 0.063041443 | V10: 0.047463152 | W10: 0.03648344 | X10: 0.035040749 | Y10: 0.023679556 | Z10: 0.019559563 | AA10: 0.017887983 | AB10: 0.015744755 | AC10: 0.015391018 | AD10: 0.01369863 | AE10: 0.0085729149 | AF10: 418.659 | AG10: 14417.5 | AH10: 7.4613491 | AI10: High risk | AJ10: Ce | AK10: 37
A11: Ce 422.260 | B11: Pr 422.293 | C11: Sm 422.066 | D11: Sm 422.371 | E11: Nd 422.113 | F11: Dy 422.111 | G11: Nd 422.320 | H11: Zr 422.430 | I11: Gd 422.000 | J11: Zr 422.238 | K11: Sm 422.186 | L11: Dy 422.221 | M11: Eu 422.388 | N11: U 422.180 | O11: Eu 422.108 | P11: Y 422.063 | Q11: 2.0366554 | R11: 0.68994736 | S11: 0.1368798 | T11: 0.085883165 | U11: 0.074536198 | V11: 0.065864182 | W11: 0.039649668 | X11: 0.026249029 | Y11: 0.024609544 | Z11: 0.022728449 | AA11: 0.015549228 | AB11: 0.014168608 | AC11: 0.013245319 | AD11: 0.012313401 | AE11: 0.01139874 | AF11: 422.26 | AG11: 11589 | AH11: 0.085883165 | AI11: Caution | AJ11: Ce | AK11: 37
A12: Ce 446.021 | B12: Sm 445.851 | C12: Nd 446.298 | D12: V 446.238 | E12: V 446.029 | F12: Zr 446.125 | G12: Pr 445.830 | H12: Mn 446.203 | I12: Th 446.106 | J12: Gd 446.324 | K12: U 446.297 | L12: Ru 446.003 | M12: Mn 445.825 | N12: Th 446.170 | O12: Fe 445.912 | P12: Mn 446.108 | Q12: 0.5855248 | R12: 0.50880819 | S12: 0.27501319 | T12: 0.12571741 | U12: 0.10789006 | V12: 0.048395226 | W12: 0.030884335 | X12: 0.029044168 | Y12: 0.028344826 | Z12: 0.02604364 | AA12: 0.017714051 | AB12: 0.016186439 | AC12: 0.013080424 | AD12: 0.010822215 | AE12: 0.0091891153 | AF12: 446.021 | AG12: 25595.5 | AH12: 0.50880819 | AI12: High risk | AJ12: Ce | AK12: 40
A13: Co 228.615 | B13: Ni 228.708 | C13: Ta 228.528 | D13: Re 228.751 | E13: Ni 228.764 | F13: Ta 228.727 | G13: Ta 228.502 | H13: Nb 228.522 | I13: Hf 228.460 | J13: Ir 228.461 | K13: Ru 228.768 | L13: Ta 228.660 | M13: Ti 228.617 | N13: Re 228.661 | O13: W 228.444 | P13: W 228.462 | Q13: 0.089901247 | R13: 0.055388164 | S13: 0.041851078 | T13: 0.026266849 | U13: 0.017905284 | V13: 0.016305053 | W13: 0.013940748 | X13: 0.0083471491 | Y13: 0.0060549268 | Z13: 0.0060549268 | AA13: 0.0050457724 | AB13: 0.0049592734 | AC13: 0.0046276941 | AD13: 0.0032437108 | AE13: 0.0031283789 | AF13: 228.615 | AG13: 6936.5 | AH13: 0.0023643048 | AI13: Excellent | AJ13: Co | AK13: 38
... A167: Yb 369.419 | B167: Dy 369.481 | C167: Sm 369.399 | D167: Tm 369.473 | E167: Tb 369.295 | F167: Th 369.390 | G167: Nd 369.481 | H167: Sm 369.431 | I167: Gd 369.404 | J167: Ce 369.491 | K167: Nb 369.589 | L167: Sm 369.278 | M167: Dy 369.441 | N167: V 369.587 | O167: Rh 369.552 | P167: Ce 369.344 | Q167: 0.029467537 | R167: 0.012518549 | S167: 0.005167061 | T167: 0.0022348353 | U167: 0.0019164563 | V167: 0.0016354077 | W167: 0.0015624112 | X167: 0.0014601685 | Y167: 0.0014544619 | Z167: 0.0012720895 | AA167: 0.0012300035 | AB167: 0.0011653291 | AC167: 0.0010849615 | AD167: 0.00088309165 | AE167: 0.00082269712 | AF167: 369.419 | AG167: 420567.9 | AH167: 0.029467537 | AI167: Good | AJ167: Yb | AK167: 40

Sheet 설명 · 출처
A1: INNO NanoLab — ICP 간섭 DB 전체 내보내기 (설명)
A3: ■ 구성
A4: · 대시보드 — 노란 칸에서 분석선을 고르면 그 피크의 상위 15개 간섭선이 막대그래프로 표시(인터랙티브).
A5: · 피크 요약 — 전체 166개 피크의 기준강도·최악 간섭·판정. 우측 그래프=원소별 가장 깨끗한 선의 REE 간섭비.
A6: · 원소 간섭 히트맵 — 분석원소(권장선)×간섭원소 강도비 색지도. 진할수록 위험.
A7: · 전체 데이터 — 6,449개 간섭선 전체(원소·파장·Δλ·강도·강도비 수식). 필터 사용 가능.
A9: ■ 강도비 / 판정
A10: 강도비 = 간섭선 강도 / 분석선 기준강도. 판정(REE): <1% Excellent · <5% Good · <20% Caution · 그 이상 High risk.
A11: 강도척도는 앱 간섭DB와 동일(원본 간섭뷰어와 검증됨). 원소 간 직접 비교 유효.
A13: ■ 데이터
A14: 총 166개 기준피크 · 기준원소 18종(Sc 포함, 신규) · 간섭선 6,449행. 앱 현재 DB(166피크)를 그대로 반영.
A15: Sc 8선(255.235·335.372·357.253·357.634·361.383·363.074·364.278·424.682)은 원본 간섭뷰어 전사분.
A17: © 2026 WonJeong Yu · INNO NanoLab — Synthesis & ICP (내부 연구용)
